Workbook

Sheet codebook
A1: discrepancy | B1: reverse | C1: jid | D1: equate_group | E1: lex_equate | F1: lex_kidsight | G1: lex_cahmi22 | H1: lex_cahmi21 | I1: lex_ne25 | J1: domain3 | K1: domain_hrtl | L1: hrtl_calibration_item | M1: param_constraints | N1: stem_combined | O1: stem_25 | P1: resp_opts25 | Q1: stem_22 | R1: resp_opts20 | S1: lex_ne22 | T1: lex_ne20 | U1: lex_ecdi | V1: lex_credi | W1: lex_gsed | X1: lex_gsed2
C2: 1 | E2: AA102 | F2: AA102 | I2: CREDI005 | J2: socemo | K2: social_emotional | N2: Does the child react differently according to the tone of your voice (e.g., smiles when you say something in a happy tone)? | O2: =VLOOKUP(I2,module6!$A$2:$C$229, 2, FALSE) -> Does the child react differently according to the tone of your voice (e.g., smiles when you say something in a happy tone)? | P2: 1 = Yes; 0 = No; -9 = Don’t Know | Q2: Does the child react differently according to the tone of your voice (e.g., smiles when you say something in a happy tone)? | S2: CREDI05
C3: 2 | E3: AA104 | F3: AA104 | I3: CREDI028 | J3: socemo | K3: social_emotional | N3: Does the child usually follow rules and obey adults (e.g., go there or don't do that)? | O3: =VLOOKUP(I3,module6!$A$2:$C$229, 2, FALSE) -> Does the child usually follow rules and obey adults (e.g., go there or don't do that)? | P3: 1 = Yes; 0 = No; -9 = Don’t Know | Q3: Does the child usually follow rules and obey adults (e.g., go there or don't do that)? | S3: CREDI28
C4: 3 | E4: AA11 | F4: AA11 | I4: C042 | J4: motor | K4: motor | N4: When lying on his/her stomach, can your child hold his/her head and chest off the ground using only his/her hands and arms for support? ????? | O4: =VLOOKUP(I4,module6!$A$2:$C$229, 2, FALSE) -> When lying on his/her stomach, can your child hold his/her head and chest off the ground using only his/her hands and arms for support? ????? | P4: 1 = Yes; 0 = No; -9 = Don’t Know | Q4: When lying on his/her stomach, can your child hold his/her head and chest off the ground using only his/her hands and arms for support? ????? | R4: Yes; No; Don't Know | S4: C042 | T4: C42 | V4: LF18 | W4: cromoc005 | X4: gpamoc042
C5: 4 | E5: AA12 | F5: AA12 | I5: C043 | J5: motor | K5: motor | N5: When lying on his/her back, does the child grab his/her feet? | O5: =VLOOKUP(I5,module6!$A$2:$C$229, 2, FALSE) -> When lying on his/her back, does the child grab his/her feet? | P5: 1 = Yes; 0 = No; -9 = Don’t Know | Q5: When lying on his/her back, does the child grab his/her feet? | R5: Yes; No; Don't Know | S5: C043 | T5: C43 | V5: LF16 | W5: cromoc009 | X5: gpamoc043
C6: 5 | E6: AA13 | F6: AA13 | I6: C047 | J6: coglan | N6: Does your child play by tapping an object on the ground or a table? | O6: =VLOOKUP(I6,module6!$A$2:$C$229, 2, FALSE) -> Does your child play by tapping an object on the ground or a table? | P6: 1 = Yes; 0 = No; -9 = Don’t Know | Q6: Does your child play by tapping an object on the ground or a table? | R6: Yes; No; Don't Know | S6: C047 | T6: C47 | V6: LF19 | W6: croclc007 | X6: gpaclc047
C7: 6 | E7: AA14 | F7: AA14 | I7: C048 | J7: coglan | K7: motor | N7: Does your child intentionally move or change his/her position to get objects that are out of reach? | O7: =VLOOKUP(I7,module6!$A$2:$C$229, 2, FALSE) -> Does your child intentionally move or change his/her position to get objects that are out of reach? | P7: 1 = Yes; 0 = No; -9 = Don’t Know | Q7: Does your child intentionally move or change his/her position to get objects that are out of reach? | R7: Yes; No; Don't Know | S7: C048 | T7: C48 | V7: LF21 | W7: croclc011 | X7: gpaclc048
C8: 7 | E8: AA15 | F8: AA15 | I8: C049 | J8: motor | K8: motor | N8: Can your child hold him/herself in a sitting position without help or support for longer than a few seconds? | O8: =VLOOKUP(I8,module6!$A$2:$C$229, 2, FALSE) -> Can your child hold him/herself in a sitting position without help or support for longer than a few seconds? | P8: 1 = Yes; 0 = No; -9 = Don’t Know | Q8: Can your child hold him/herself in a sitting position without help or support for longer than a few seconds? | R8: Yes; No; Don't Know | S8: C049 | T8: C49 | V8: LF20 | W8: cromoc011 | X8: gpamoc049
C9: 8 | E9: AA17 | F9: AA17 | I9: C054 | J9: motor | K9: motor | N9: Can your child maintain a standing position while holding on to a person or object (e.g., wall or furniture)? | O9: =VLOOKUP(I9,module6!$A$2:$C$229, 2, FALSE) -> Can your child maintain a standing position while holding on to a person or object (e.g., wall or furniture)? | P9: 1 = Yes; 0 = No; -9 = Don’t Know | Q9: Can your child maintain a standing position while holding on to a person or object (e.g., wall or furniture)? | R9: Yes; No; Don't Know | S9: C054 | T9: C54 | V9: LF29 | W9: cromoc015 | X9: gpamoc054
C10: 9 | E10: AA19 | F10: AA19 | I10: C060 | J10: motor | K10: motor | N10: Can your child walk several steps while holding on to a person or object (e.g., wall or furniture)? | O10: =VLOOKUP(I10,module6!$A$2:$C$229, 2, FALSE) -> Can your child walk several steps while holding on to a person or object (e.g., wall or furniture)? | P10: 1 = Yes; 0 = No; -9 = Don’t Know | Q10: Can your child walk several steps while holding on to a person or object (e.g., wall or furniture)? | R10: Yes; No; Don't Know | S10: C060 | T10: C60 | V10: LF34 | W10: cromoc018 | X10: gpamoc060
C11: 10 | E11: AA20 | F11: AA20 | I11: C062 | J11: motor | K11: motor | N11: Can your child maintain a standing position on his/her own, without holding on or receiving support? | O11: =VLOOKUP(I11,module6!$A$2:$C$229, 2, FALSE) -> Can your child maintain a standing position on his/her own, without holding on or receiving support? | P11: 1 = Yes; 0 = No; -9 = Don’t Know | Q11: Can your child maintain a standing position on his/her own, without holding on or receiving support? | R11: Yes; No; Don't Know | S11: C062 | T11: C62 | V11: LF36 | W11: cromoc017 | X11: gpamoc062
C12: 11 | E12: =F12 -> AA201 | F12: AA201 | I12: SF018 | J12: motor | K12: motor | N12: While your child is on his/her back, can he/she bring his/her hands together such that the hands touch each other? | O12: =VLOOKUP(I12,module6!$A$2:$C$229, 2, FALSE) -> While your child is on his/her back, can he/she bring his/her hands together such that the hands touch each other? | P12: 1 = Yes; 0 = No; -9 = Don’t Know | Q12: While your child is on his/her back, can he/she bring his/her hands together such that the hands touch each other?
C13: 12 | E13: =F13 -> AA202 | F13: AA202 | I13: SF019 | J13: motor | K13: motor | N13: Does your child move excitedly, kick legs, move arms or trunk, or make coo noises when a known person enters the room or speaks to him/her? | O13: =VLOOKUP(I13,module6!$A$2:$C$229, 2, FALSE) -> Does your child move excitedly, kick legs, move arms or trunk, or make coo noises when a known person enters the room or speaks to him/her? | P13: 1 = Yes; 0 = No; -9 = Don’t Know | Q13: Does your child move excitedly, kick legs, move arms or trunk, or make coo noises when a known person enters the room or speaks to him/her?
C14: 13 | E14: =F14 -> AA203 | F14: AA203 | I14: SF021 | J14: socemo | K14: social_emotional | N14: If you play a game with your child, does he/she respond with interest? For example, if you play peek-a-boo, pat-a-cake, wave bye-bye, etc. does your child smile, widen his/her eyes, kick or move arms or vocalize? | O14: =VLOOKUP(I14,module6!$A$2:$C$229, 2, FALSE) -> If you play a game with your child, does he/she respond with interest? For example, if you play peek-a-boo, pat-a-cake, wave bye-bye, etc. does your child smile, widen his/her eyes, kick or move arms or vocalize? | P14: 1 = Yes; 0 = No; -9 = Don’t Know | Q14: If you play a game with your child, does he/she respond with interest? For example, if you play peek-a-boo, pat-a-cake, wave bye-bye, etc. does your child smile, widen his/her eyes, kick or move arms or vocalize?
C15: 14 | E15: =F15 -> AA205 | F15: AA205 | I15: SF093 | J15: socemo | N15: Does your child show independence (e.g., wants to go to visit a friend's house)? | O15: =VLOOKUP(I15,module6!$A$2:$C$229, 2, FALSE) -> Does your child show independence (e.g., wants to go to visit a friend's house)? | P15: 1 = Yes; 0 = No; -9 = Don’t Know | Q15: Does your child show independence (e.g., wants to go to visit a friend's house)?
C16: 15 | E16: AA21 | F16: AA21 | I16: C065 | J16: motor | K16: motor | N16: Can your child climb onto an object (rock, porch, step, chair, bed, low table, etc.)? | O16: =VLOOKUP(I16,module6!$A$2:$C$229, 2, FALSE) -> Can your child climb onto an object (rock, porch, step, chair, bed, low table, etc.)? | P16: 1 = Yes; 0 = No; -9 = Don’t Know | Q16: Can your child climb onto an object (rock, porch, step, chair, bed, low table, etc.)? | R16: Yes; No; Don't Know | S16: C065 | T16: C65 | V16: LF44 | W16: iyomoc022 | X16: gpamoc065
C17: 16 | E17: AA24 | F17: AA24 | I17: C089 | J17: coglan | K17: early_learning | N17: Can your child say five or more separate words (e.g., names like "Mama" or objects like "ball")? | O17: =VLOOKUP(I17,module6!$A$2:$C$229, 2, FALSE) -> Can your child say five or more separate words (e.g., names like "Mama" or objects like "ball")? | P17: 1 = Yes; 0 = No; -9 = Don’t Know | Q17: Can your child say five or more separate words (e.g., names like "Mama" or objects like "ball")? | R17: Yes; No; Don't Know | S17: C089 | T17: C89 | V17: LF58 | W17: mdtsed019 | X17: gpasec089
C18: 17 | E18: AA26 | F18: AA26 | I18: C093 | J18: coglan | K18: early_learning | N18: Can your child ask for something (e.g., food, water) by name when he/she wants it? | O18: =VLOOKUP(I18,module6!$A$2:$C$229, 2, FALSE) -> Can your child ask for something (e.g., food, water) by name when he/she wants it? | P18: 1 = Yes; 0 = No; -9 = Don’t Know | Q18: Can your child ask for something (e.g., food, water) by name when he/she wants it? | R18: Yes; No; Don't Know | S18: C093 | T18: C93 | V18: LF62 | W18: croclc025 | X18: gpaclc093
C19: 18 | E19: AA27 | F19: AA27 | I19: C096 | J19: coglan | K19: early_learning | N19: Can your child correctly name at least one family member other than mom and dad (e.g., name of brother, sister, aunt, uncle)? | O19: =VLOOKUP(I19,module6!$A$2:$C$229, 2, FALSE) -> Can your child correctly name at least one family member other than mom and dad (e.g., name of brother, sister, aunt, uncle)? | P19: 1 = Yes; 0 = No; -9 = Don’t Know | Q19: Can your child correctly name at least one family member other than mom and dad (e.g., name of brother, sister, aunt, uncle)? | R19: Yes; No; Don't Know | S19: C096 | T19: C96 | V19: LF64 | W19: croclc028 | X19: gpaclc096
C20: 19 | E20: AA28 | F20: AA28 | I20: C097 | J20: motor | K20: motor | N20: Can your child walk on an uneven surface (e.g., a bumpy or steep road) without falling? | O20: =VLOOKUP(I20,module6!$A$2:$C$229, 2, FALSE) -> Can your child walk on an uneven surface (e.g., a bumpy or steep road) without falling? | P20: 1 = Yes; 0 = No; -9 = Don’t Know | Q20: Can your child walk on an uneven surface (e.g., a bumpy or steep road) without falling? | R20: Yes; No; Don't Know | S20: C097 | T20: C97 | U20: ECDI1 | V20: LF60 | W20: cromoc031 | X20: gpamoc097
C21: 20 | E21: AA29 | F21: AA29 | I21: C100 | J21: coglan | K21: early_learning | N21: Can your child name at least two body parts (e.g., arm, eye, or nose)? | O21: =VLOOKUP(I21,module6!$A$2:$C$229, 2, FALSE) -> Can your child name at least two body parts (e.g., arm, eye, or nose)? | P21: 1 = Yes; 0 = No; -9 = Don’t Know | Q21: Can your child name at least two body parts (e.g., arm, eye, or nose)? | R21: Yes; No; Don't Know | S21: C100 | T21: C100 | V21: LF71 | W21: croclc038 | X21: gpaclc100
C22: 21 | E22: AA30 | F22: AA30 | I22: C101 | J22: coglan | K22: early_learning | N22: If you show your child an object he/she knows well (e.g., a cup or animal), can he/she consistently name it? | O22: =VLOOKUP(I22,module6!$A$2:$C$229, 2, FALSE) -> If you show your child an object he/she knows well (e.g., a cup or animal), can he/she consistently name it? | P22: 1 = Yes; 0 = No; -9 = Don’t Know | Q22: If you show your child an object he/she knows well (e.g., a cup or animal), can he/she consistently name it? | R22: Yes; No; Don't Know | S22: C101 | T22: C101 | U22: ECDI9 | V22: LF72 | W22: croclc034 | X22: gpaclc101
C23: 22 | E23: AA31 | F23: AA31 | I23: C104 | J23: motor | K23: motor | N23: Can your child remove an item of clothing (e.g., take off his/her shirt)? | O23: =VLOOKUP(I23,module6!$A$2:$C$229, 2, FALSE) -> Can your child remove an item of clothing (e.g., take off his/her shirt)? | P23: 1 = Yes; 0 = No; -9 = Don’t Know | Q23: Can your child remove an item of clothing (e.g., take off his/her shirt)? | R23: Yes; No; Don't Know | S23: C104 | T23: C104 | V23: LF77 | W23: cromoc035 | X23: gpamoc104
C24: 23 | E24: AA34 | F24: AA34 | I24: C110 | J24: motor | K24: motor | N24: Can your child unscrew the lid from a bottle or jar? | O24: =VLOOKUP(I24,module6!$A$2:$C$229, 2, FALSE) -> Can your child unscrew the lid from a bottle or jar? | P24: 1 = Yes; 0 = No; -9 = Don’t Know | Q24: Can your child unscrew the lid from a bottle or jar? | R24: Yes; No; Don't Know | S24: C110 | T24: C110 | V24: LF86 | W24: cromoc033 | X24: gpamoc110
C25: 24 | E25: AA36 | F25: AA36 | I25: C113 | J25: coglan | K25: early_learning | N25: Can your child correctly use any of the words "I," "you," "she," or "he" (e.g., "I go to store," or "He eats rice")? | O25: =VLOOKUP(I25,module6!$A$2:$C$229, 2, FALSE) -> Can your child correctly use any of the words "I," "you," "she," or "he" (e.g., "I go to store," or "He eats rice")? | P25: 1 = Yes; 0 = No; -9 = Don’t Know | Q25: Can your child correctly use any of the words "I," "you," "she," or "he" (e.g., "I go to store," or "He eats rice")? | R25: Yes; No; Don't Know | S25: C113 | T25: C113 | U25: ECDI8 | V25: LF88 | W25: croclc031 | X25: gpaclc113
C26: 25 | E26: AA38 | F26: AA38 | I26: C116 | J26: coglan | K26: early_learning | N26: Does your child pronounce most of his/her words correctly? | O26: =VLOOKUP(I26,module6!$A$2:$C$229, 2, FALSE) -> Does your child pronounce most of his/her words correctly? | P26: 1 = Yes; 0 = No; -9 = Don’t Know | Q26: Does your child pronounce most of his/her words correctly? | R26: Yes; No; Don't Know | S26: C116 | T26: C116 | V26: LF89 | W26: croclc046 | X26: gpaclc116
C27: 26 | E27: AA4 | F27: AA4 | I27: C020 | J27: socemo | K27: self_regulation | N27: Does your child sometimes suck his/her thumb or fingers? | O27: =VLOOKUP(I27,module6!$A$2:$C$229, 2, FALSE) -> Does your child sometimes suck his/her thumb or fingers? | P27: 1 = Yes; 0 = No; -9 = Don’t Know | Q27: Does your child sometimes suck his/her thumb or fingers? | R27: Yes; No; Don't Know | S27: C020 | T27: C20 | V27: LF5 | W27: crosec004 | X27: gpasec020
C28: 27 | E28: AA41 | F28: AA41 | I28: C119 | J28: coglan | K28: early_learning | N28: Can your child explain in words what common objects like a cup or chair are used for? | O28: =VLOOKUP(I28,module6!$A$2:$C$229, 2, FALSE) -> Can your child explain in words what common objects like a cup or chair are used for? | P28: 1 = Yes; 0 = No; -9 = Don’t Know | Q28: Can your child explain in words what common objects like a cup or chair are used for? | R28: Yes; No; Don't Know | S28: C119 | T28: C119 | V28: LF97 | W28: croclc039 | X28: gpaclc119
C29: 28 | E29: AA43 | F29: AA43 | I29: C121 | J29: coglan | K29: early_learning | N29: Does your child regularly use describing words such as "fast," "short," "hot," "fat," or "beautiful" correctly? | O29: =VLOOKUP(I29,module6!$A$2:$C$229, 2, FALSE) -> Does your child regularly use describing words such as "fast," "short," "hot," "fat," or "beautiful" correctly? | P29: 1 = Yes; 0 = No; -9 = Don’t Know | Q29: Does your child regularly use describing words such as "fast," "short," "hot," "fat," or "beautiful" correctly? | R29: Yes; No; Don't Know | S29: C121 | T29: C121 | V29: LF95 | W29: croclc050 | X29: gpaclc121
C30: 29 | E30: AA46 | F30: AA46 | I30: C132 | J30: motor | K30: motor | N30: Can your child fasten and unfasten buttons without help? | O30: =VLOOKUP(I30,module6!$A$2:$C$229, 2, FALSE) -> Can your child fasten and unfasten buttons without help? | P30: 1 = Yes; 0 = No; -9 = Don’t Know | Q30: Can your child fasten and unfasten buttons without help? | R30: Yes; No; Don't Know | S30: C132 | T30: C132 | U30: ECDI4 | V30: LF105 | W30: cromoc039 | X30: gpamoc132
C31: 30 | E31: AA47 | F31: AA47 | I31: C136 | J31: coglan | K31: early_learning | N31: Can your child say what others like or dislike (e.g., "Mama doesn't like fruit," Papa likes football)? | O31: =VLOOKUP(I31,module6!$A$2:$C$229, 2, FALSE) -> Can your child say what others like or dislike (e.g., "Mama doesn't like fruit," Papa likes football)? | P31: 1 = Yes; 0 = No; -9 = Don’t Know | Q31: Can your child say what others like or dislike (e.g., "Mama doesn't like fruit," Papa likes football)? | R31: Yes; No; Don't Know | S31: C136 | T31: C136 | V31: LF104 | W31: crosec051 | X31: gpasec136
C32: 31 | E32: AA49 | F32: AA49 | I32: C139 | J32: coglan | K32: early_learning | N32: Can your child talk about things that will happen in the future using correct language (e.g., "Tomorrow he will attend school" or "Next week we will go to the market")? | O32: =VLOOKUP(I32,module6!$A$2:$C$229, 2, FALSE) -> Can your child talk about things that will happen in the future using correct language (e.g., "Tomorrow he will attend school" or "Next week we will go to the market")? | P32: 1 = Yes; 0 = No; -9 = Don’t Know | Q32: Can your child talk about things that will happen in the future using correct language (e.g., "Tomorrow he will attend school" or "Next week we will go to the market")? | R32: Yes; No; Don't Know | S32: C139 | T32: C139 | V32: LF106 | W32: croclc048 | X32: gpaclc139
C33: 32 | E33: AA5 | F33: AA5 | I33: C023 | J33: coglan | N33: Does your child laugh? | O33: =VLOOKUP(I33,module6!$A$2:$C$229, 2, FALSE) -> Does your child laugh? | P33: 1 = Yes; 0 = No; -9 = Don’t Know | Q33: Does your child laugh? | R33: Yes; No; Don't Know | S33: C023 | T33: C23 | V33: LF3 | W33: croclc006 | X33: gpaclc023
C34: 33 | E34: AA50 | F34: AA50 | I34: CREDI001 | J34: socemo | N34: Does the child smile when others smile at him/her? | O34: =VLOOKUP(I34,module6!$A$2:$C$229, 2, FALSE) -> Does the child smile when others smile at him/her? | P34: 1 = Yes; 0 = No; -9 = Don’t Know | Q34: Does the child smile when others smile at him/her? | S34: CREDI01 | V34: LF4
C35: 34 | E35: AA54 | F35: AA54 | I35: CREDI017 | J35: socemo | K35: social_emotional | N35: Does the child often show affection toward others (e.g., hugging parents, brothers, or sisters)? | O35: =VLOOKUP(I35,module6!$A$2:$C$229, 2, FALSE) -> Does the child often show affection toward others (e.g., hugging parents, brothers, or sisters)? | P35: 1 = Yes; 0 = No; -9 = Don’t Know | Q35: Does the child often show affection toward others (e.g., hugging parents, brothers, or sisters)? | S35: CREDI17 | V35: LF13
C36: 35 | E36: AA55 | F36: AA55 | I36: CREDI019 | J36: socemo | N36: Can the child indicate when he/she needs to go to the toilet? | O36: =VLOOKUP(I36,module6!$A$2:$C$229, 2, FALSE) -> Can the child indicate when he/she needs to go to the toilet? | P36: 1 = Yes; 0 = No; -9 = Don’t Know | Q36: Can the child indicate when he/she needs to go to the toilet? | S36: CREDI19 | V36: LF75
C37: 36 | E37: AA56 | F37: AA56 | I37: CREDI020 | J37: socemo | K37: self_regulation | N37: Can the child sit or play on his/her own for at least 20 minutes? | O37: =VLOOKUP(I37,module6!$A$2:$C$229, 2, FALSE) -> Can the child sit or play on his/her own for at least 20 minutes? | P37: 1 = Yes; 0 = No; -9 = Don’t Know | Q37: Can the child sit or play on his/her own for at least 20 minutes? | S37: CREDI20 | V37: LF39
C38: 37 | E38: AA57 | F38: AA57 | I38: CREDI021 | J38: socemo | K38: self_regulation | N38: Does the child listen to someone telling a story with interest? | O38: =VLOOKUP(I38,module6!$A$2:$C$229, 2, FALSE) -> Does the child listen to someone telling a story with interest? | P38: 1 = Yes; 0 = No; -9 = Don’t Know | Q38: Does the child listen to someone telling a story with interest? | S38: CREDI21 | V38: LF61
C39: 38 | E39: AA6 | F39: AA6 | I39: C026 | J39: motor | K39: motor | N39: Does your child grasp onto a small object (e.g., your finger, a spoon) when out in his/her hand? | O39: =VLOOKUP(I39,module6!$A$2:$C$229, 2, FALSE) -> Does your child grasp onto a small object (e.g., your finger, a spoon) when out in his/her hand? | P39: 1 = Yes; 0 = No; -9 = Don’t Know | Q39: Does your child grasp onto a small object (e.g., your finger, a spoon) when out in his/her hand? | R39: Yes; No; Don't Know | S39: C026 | T39: C26 | V39: LF6 | W39: cromoc006 | X39: gpamoc026
C40: 39 | E40: AA60 | F40: AA60 | I40: CREDI025 | J40: socemo | K40: social_emotional | N40: Does the child imitate others' behaviors (e.g., washing hands or dishes)? | O40: =VLOOKUP(I40,module6!$A$2:$C$229, 2, FALSE) -> Does the child imitate others' behaviors (e.g., washing hands or dishes)? | P40: 1 = Yes; 0 = No; -9 = Don’t Know | Q40: Does the child imitate others' behaviors (e.g., washing hands or dishes)? | S40: CREDI25 | V40: LF55
...

Sheet module6
A1: lex_ne25 | B1: stem | C1: resp_opts
A2: C016 | B2: Does your child stop crying or calm down when you come to the room after being out of sight, or when you pick him or her up? | C2: Yes; No; Don’t Know
A3: C020 | B3: Does your child sometimes suck his/her thumb or fingers? | C3: Yes; No; Don’t Know
A4: C021 | B4: Does your child turn his/her head towards your voice or some noise? | C4: Yes; No; Don’t Know
A5: C007 | B5: Does your child look at a person when that person starts talking or making noise? | C5: Yes; No; Don’t Know
A6: C013 | B6: When your child is on his/her stomach, can he/she turn his/her head to the side? | C6: Yes; No; Don’t Know
A7: SF018 | B7: While your child is on his/her back, can he/she bring his/her hands together such that the hands touch each other? | C7: Yes; No; Don’t Know
A8: C015 | B8: Does your child look at your face when you speak to him/her? | C8: Yes; No; Don’t Know
A9: C024 | B9: Can your child hold his/her head steady for at least a few seconds, without it flopping to the side? | C9: Yes; No; Don’t Know
A10: C005 | B10: Does your child try to move his/her head (or eyes) to follow an object or person? | C10: Yes; No; Don’t Know
A11: C012 | B11: When you talk to your child, does he/she smile, make noise, or more arms, legs or trunk in response? | C11: Yes; No; Don’t Know
A12: C018 | B12: When your child is on his/her stomach, can he/she hold his/her head up off the ground? | C12: Yes; No; Don’t Know
... A229: NOM054X | B229: How often does this child get easily distracted? | C229: Always; Most of the time; About half the time; Sometimes; Never

Sheet Modules_Lf
A1: lex_ne25 | B1: stem | C1: illustration | D1: resp_opts | E1: num_code | F1: type | H1: ES_stem | I1: ES_similarity_stem | J1: ES_resp_opts | K1: ES_num_code
A2: C004 | B2: Does your child smile? | C2: SF001.png | D2: Yes; No; Don’t Know | E2: 1 = Yes; 0 = No; -9 = Don’t Know | F2: Single selection | H2: ¿El niño/la niña reacciona de manera diferente según el tono de su voz (por ejemplo, sonríe cuando dice algo en un tono alegre)? | I2: 1 | J2: Sí; No; No sé | K2: 1 = Sí; 0 = No; -9 = No sé
A3: C005 | B3: Does your child try to move his/her head (or eyes) to follow an object or person? | C3: SF008.png | D3: Yes; No; Don’t Know | E3: 1 = Yes; 0 = No; -9 = Don’t Know | F3: Single selection | H3: Cuando Ud. le habla a su bebé, ¿le responde sonriendo, haciendo algún sonido o moviendo los brazos, las piernas o el tronco? | I3: 1 | J3: Sí; No; No sé | K3: 1 = Sí; 0 = No; -9 = No sé
A4: C007 | B4: Does your child look at a person when that person starts talking or making noise? | C4: NA | D4: Yes; No; Don’t Know | E4: 1 = Yes; 0 = No; -9 = Don’t Know | F4: Single selection | H4: Cuando su bebé está boca abajo, ¿puede girar la cabeza hacia un costado? | I4: 1 | J4: Sí; No; No sé | K4: 1 = Sí; 0 = No; -9 = No sé
A5: C010 | B5: Does your child smile when you smile or talk with him/her? | C5: NA | D5: Yes; No; Don’t Know | E5: 1 = Yes; 0 = No; -9 = Don’t Know | F5: Single selection | H5: Cuando su bebé está mirando algún juguete o persona, ¿produce sonidos (distintos al llanto)? | I5: 1 | J5: Sí; No; No sé | K5: 1 = Sí; 0 = No; -9 = No sé
A6: C012 | B6: When you talk to your child, does he/she smile, make noise, or more arms, legs or trunk in response? | C6: NA | D6: Yes; No; Don’t Know | E6: 1 = Yes; 0 = No; -9 = Don’t Know | F6: Single selection | H6: Cuando su bebé está boca abajo, ¿puede mantener la cabeza levantada (esto es, separada del suelo)? | I6: 1 | J6: Sí; No; No sé | K6: 1 = Sí; 0 = No; -9 = No sé
A7: C013 | B7: When your child is on his/her stomach, can he/she turn his/her head to the side? | C7: SF025.png | D7: Yes; No; Don’t Know | E7: 1 = Yes; 0 = No; -9 = Don’t Know | F7: Single selection | H7: Cuando su bebé está boca arriba, ¿puede juntar las manos? | I7: 0.57894737 | J7: Sí; No; No sé | K7: 1 = Sí; 0 = No; -9 = No sé
A8: C014 | B8: When you are about to pick up your child, does he/she act happy or excited? | C8: NA | D8: Yes; No; Don’t Know | E8: 1 = Yes; 0 = No; -9 = Don’t Know | F8: Single selection | H8: Si juega con su bebé, ¿responde con interés? Por ejemplo, si juega al cucú, esconderse tapándose los ojos, a aplaudir, a decir adiós con la mano, etc., ¿su bebé sonríe, abre bien los ojos, da pataditas o mueve los brazos, o vocaliza? | I8: 0.87096774 | J8: Sí; No; No sé | K8: 1 = Sí; 0 = No; -9 = No sé
A9: C015 | B9: Does your child look at your face when you speak to him/her? | C9: SF003.png | D9: Yes; No; Don’t Know | E9: 1 = Yes; 0 = No; -9 = Don’t Know | F9: Single selection | H9: ¿Su bebé puede mantener la cabeza firme sin que se le caiga hacia un costado por al menos unos pocos segundos? | I9: 1 | J9: Sí; No; No sé | K9: 1 = Sí; 0 = No; -9 = No sé
A10: C016 | B10: Does your child stop crying or calm down when you come to the room after being out of sight, or when you pick him or her up? | C10: NA | D10: Yes; No; Don’t Know | E10: 1 = Yes; 0 = No; -9 = Don’t Know | F10: Single selection | H10: ¿Su bebé se chupa a veces el pulgar o los otros dedos? | I10: 1 | J10: Sí; No; No sé | K10: 1 = Sí; 0 = No; -9 = No sé
A11: C017 | B11: While your child is on his/her back, can he/she bring his/her hands together? | C11: NA | D11: Yes; No; Don’t Know | E11: 1 = Yes; 0 = No; -9 = Don’t Know | F11: Single selection | H11: ¿Su bebé sonríe? | I11: 1 | J11: Sí; No; No sé | K11: 1 = Sí; 0 = No; -9 = No sé
A12: C018 | B12: When your child is on his/her stomach, can he/she hold his/her head up off the ground? | C12: SF031.png | D12: Yes; No; Don’t Know | E12: 1 = Yes; 0 = No; -9 = Don’t Know | F12: Single selection | H12: Cuando su bebé está boca arriba, ¿puede juntar las manos? | I12: 1 | J12: Sí; No; No sé | K12: 1 = Sí; 0 = No; -9 = No sé
A13: C019 | B13: Does your child make noise or gesture to get your attention? | C13: NA | D13: Yes; No; Don’t Know | E13: 1 = Yes; 0 = No; -9 = Don’t Know | F13: Single selection | H13: ¿Su bebé sonríe cuando Ud. le sonríe o le habla? | I13: 1 | J13: Sí; No; No sé | K13: 1 = Sí; 0 = No; -9 = No sé
... A207: NOM053X | B207: How often can this child recognize and name their own emotions? | C207: NA | D207: Always; Most of the time; About half the time; Sometimes; Never | E207: 4 = Always; 3 = Most of the time; 2 = About half the time; 1 = Sometimes; 0 = Never | F207: Single selection | H207: ¿Puede este niño/a identificar: un triángulo? | I207: 1 | J207: Sí; No | K207: 1 = Sí; 0 = No
A208: NOM054X | B208: How often does this child get easily distracted? | C208: NA | D208: Always; Most of the time; About half the time; Sometimes; Never | E208: 4 = Always; 3 = Most of the time; 2 = About half the time; 1 = Sometimes; 0 = Never | F208: Single selection | H208: #N/A | I208: #N/A | J208: #N/A | K208: #N/A
A209: NOM056X | B209: How often does this child have difficulty waiting for their turn? | C209: NA | D209: Always; Most of the time; About half the time; Sometimes; Never | E209: 4 = Always; 3 = Most of the time; 2 = About half the time; 1 = Sometimes; 0 = Never | F209: Single selection | H209: ¿Con qué frecuencia este niño/a tiene problemas para calmarse? | I209: 1 | J209: Siempre; La mayor parte del tiempo; ABOUT HALF THE TIME; Algunas veces; Nunca | K209: 4 = Siempre; 3 = La mayor parte del tiempo; 2 = ABOUT HALF THE TIME; 1 = Algunas veces; 0 = Nunca
A210: NOM057 | B210: How often does child take turns during games or fun activities? | C210: NA | D210: All of the time; Most of the time; Half of the time; Some of the time; None of the time | E210: 4 = All of the time; 3 = Most of the time; 2 = Half of the time; 1 = Some of the time; 0 = None of the time | F210: Single selection | H210: ¿Con qué frecuencia este niño/a puede explicar cosas que ha visto o hecho para que usted entienda? | I210: 1 | J210: Todo el tiempo; La mayor parte del tiempo; La mitad del tiempo; Algunas veces; Nunca | K210: 4 = Todo el tiempo; 3 = La mayor parte del tiempo; 2 = La mitad del tiempo; 1 = Algunas veces; 0 = Nunca
A211: NOM059 | B211: How often does this child show concern when they see others are hurt or unhappy? | C211: NA | D211: Always; Most of the time; About half of the time; Some of the time; None of the time | E211: 4 = Always; 3 = Most of the time; 2 = About half of the time; 1 = Some of the time; 0 = None of the time | F211: Single selection | H211: ¿Con qué frecuencia este niño/a sigue trabajando en una tarea cuando las cosas no funcionan? | I211: 0.45454545 | J211: Siempre; La mayor parte del tiempo; ABOUT HALF THE TIME; Algunas veces; Nunca | K211: 4 = Siempre; 3 = La mayor parte del tiempo; 2 = ABOUT HALF THE TIME; 1 = Algunas veces; 0 = Nunca
A212: NOM059X | B212: How often does this child keep working on a task even when it is hard for them? | C212: NA | D212: Always; Most of the time; About half the time; Sometimes; Never | E212: 4 = Always; 3 = Most of the time; 2 = About half the time; 1 = Sometimes; 0 = Never | F212: Single selection | H212: Cuando dices una palabra, ¿con qué frecuencia este niño/a puede pensar en otra palabra que comience con el mismo sonido? | I212: 1 | J212: Todo el tiempo; La mayor parte del tiempo; La mitad del tiempo; Algunas veces; Nunca | K212: 4 = Todo el tiempo; 3 = La mayor parte del tiempo; 2 = La mitad del tiempo; 1 = Algunas veces; 0 = Nunca
A213: NOM060Y | B213: How often does this child have trouble calming down? | C213: NA | D213: Always; Most of the time; About half the time; Sometimes; Never | E213: 4 = Always; 3 = Most of the time; 2 = About half the time; 1 = Sometimes; 0 = Never | F213: Single selection | H213: ¿Con qué frecuencia este niño/a tiene dificultades al moverse entre una actividad y una nueva? | I213: 0.61904762 | J213: Siempre; La mayor parte del tiempo; ABOUT HALF THE TIME; Algunas veces; Nunca | K213: 4 = Siempre; 3 = La mayor parte del tiempo; 2 = ABOUT HALF THE TIME; 1 = Algunas veces; 0 = Nunca
A214: NOM061 | B214: Child bounces back easily when things do not go his/her way. | C214: NA | D214: All of the time; Most of the time; Half of the time; Some of the time; None of the time | E214: 4 = All of the time; 3 = Most of the time; 2 = Half of the time; 1 = Some of the time; 0 = None of the time | F214: Single selection | H214: El niño/a se recupera fácilmente cuando las cosas no salen a su manera. | I214: 0.41176471 | J214: Siempre; Casi siempre; Algunas veces; Nunca | K214: 3 = Siempre; 2 = Casi siempre; 1 = Algunas veces; 0 = Nunca
A215: NOM061X | B215: Does this child bounce back quickly when things do not go their way? | C215: NA | D215: Always; Usually; Sometimes; Never | E215: 3 = Always; 2 = Usually; 1 = Sometimes; 0 = Never | F215: Single selection | H215: ¿Puede este niño/a dibujar un: cuadrado? | I215: 1 | J215: Sí; No | K215: 1 = Sí; 0 = No
A216: NOM062Y | B216: How often does this child have difficulty when asked to end one activity and start a new activity? | C216: NA | D216: Always; Most of the time; About half the time; Sometimes; Never | E216: 4 = Always; 3 = Most of the time; 2 = About half the time; 1 = Sometimes; 0 = Never | F216: Single selection | H216: ¿Con qué frecuencia sigue trabajando este niño/a en una tarea después de los contratiempos? | I216: 0.42105263 | J216: Siempre; La mayor parte del tiempo; ABOUT HALF THE TIME; Algunas veces; Nunca | K216: 4 = Siempre; 3 = La mayor parte del tiempo; 2 = ABOUT HALF THE TIME; 1 = Algunas veces; 0 = Nunca
A217: NOM102 | B217: How often does this child keep working at something until he or she is finished? | C217: NA | D217: Always; Most of the time; About half the time; Sometimes; Never | E217: 4 = Always; 3 = Most of the time; 2 = About half the time; 1 = Sometimes; 0 = Never | F217: Single selection | H217: ¿Cuántas veces se ha mudado este(a) niño(a) a una nueva dirección desde que nació? | I217: 0.28571429 | J217: Siempre; La mayor parte del tiempo; ABOUT HALF THE TIME; Algunas veces; Nunca | K217: 4 = Siempre; 3 = La mayor parte del tiempo; 2 = ABOUT HALF THE TIME; 1 = Algunas veces; 0 = Nunca
A218: NOM103 | B218: When this child is paying attention, how often can he or she follow instructions to complete a simple task? | C218: NA | D218: Always; Most of the time; About half the time; Sometimes; Never | E218: 4 = Always; 3 = Most of the time; 2 = About half the time; 1 = Sometimes; 0 = Never | F218: Single selection | H218: ¿Su niño/a no puede quedarse quieto? | I218: 0.3125 | J218: Siempre; La mayor parte del tiempo; ABOUT HALF THE TIME; Algunas veces; Nunca | K218: 4 = Siempre; 3 = La mayor parte del tiempo; 2 = ABOUT HALF THE TIME; 1 = Algunas veces; 0 = Nunca
A219: NOM104 | B219: Compared to other children their age, how often is this child able to sit still? | C219: NA | D219: Always; Most of the time; About half the time; Sometimes; Never | E219: 4 = Always; 3 = Most of the time; 2 = About half the time; 1 = Sometimes; 0 = Never | F219: Single selection | H219: ¿Su niño/niña puede pararse en un pie sin ningún apoyo por al menos unos segundos? | I219: 0.28571429 | J219: Siempre; La mayor parte del tiempo; ABOUT HALF THE TIME; Algunas veces; Nunca | K219: 4 = Siempre; 3 = La mayor parte del tiempo; 2 = ABOUT HALF THE TIME; 1 = Algunas veces; 0 = Nunca
A220: NOM2202 | B220: How often can this child focus on a task you give them for at least a few minutes? For example, can this child focus on simple chores? | C220: NA | D220: Always; Most of the time; About half the time; Sometimes; Never | E220: 4 = Always; 3 = Most of the time; 2 = About half the time; 1 = Sometimes; 0 = Never | F220: Single selection | H220: ¿Con qué frecuencia puede este niño/a reconocer el sonido inicial de una palabra? Por ejemplo, ¿la palabra "pelota" comienza con el sonido "pe"? | I220: 0.27272727 | J220: Siempre; La mayor parte del tiempo; ABOUT HALF THE TIME; Algunas veces; Nunca | K220: 4 = Siempre; 3 = La mayor parte del tiempo; 2 = ABOUT HALF THE TIME; 1 = Algunas veces; 0 = Nunca
... A229: SF127 | B229: If you ask your child to give you three objects (e.g., stones, beans), does the child give you the correct number? | C229: NA | D229: Yes; No; Don’t Know | E229: 1 = Yes; 0 = No; -9 = Don’t Know | F229: Single selection | H229: ¿Su niño/niña pregunta "por qué" (p. ej., "¿Por qué eres alto?")? | I229: 0.57142857 | J229: Sí; No; No sé | K229: 1 = Sí; 0 = No; -9 = No sé

Sheet Metadata_Qualtrics_22mar2022
A1: Item_Code | B1: label | C1: Item_guide_information | D1: Start_age | E1: Stop_age | F1: Resp_opts | G1: Form | H1: min_days | I1: max_days | J1: recoded_options | K1: var_type
A2: C1 | B2: Does your child cry when he/she is hungry, wet, tired, or wants to be held? | C2: GSED SF | D2: 0 months | E2: 42 months | F2: Yes; No; Don't Know | G2: All (Age Band Rules) | H2: 0 | I2: 1274 | J2: No; Yes | K2: ordered
A3: C2 | B3: Does your child look at and focus on objects in front of him/her? | C3: GSED SF | D3: 0 months | E3: 42 months | F3: Yes; No; Don't Know | G3: All (Age Band Rules) | H3: 0 | I3: 1274 | J3: No; Yes | K3: ordered
A4: C3 | B4: Does your child grasp your finger if you touch her hand? | C4: GSED SF | D4: 0 months | E4: 42 months | F4: Yes; No; Don't Know | G4: All (Age Band Rules) | H4: 0 | I4: 1274 | J4: No; Yes | K4: ordered
A5: C4 | B5: Does your child smile? | C5: GSED SF | D5: 0 months | E5: 42 months | F5: Yes; No; Don't Know | G5: All (Age Band Rules) | H5: 0 | I5: 1274 | J5: No; Yes | K5: ordered
A6: C5 | B6: Does your child try to move his/her head (or eyes) to follow an object or person? | C6: GSED SF | D6: 0 months | E6: 42 months | F6: Yes; No; Don't Know | G6: All (Age Band Rules) | H6: 0 | I6: 1274 | J6: No; Yes | K6: ordered
A7: C6 | B7: When lying on his/her back, does your child move his/her arms and legs? | C7: GSED SF | D7: 0 months | E7: 42 months | F7: Yes; No; Don't Know | G7: All (Age Band Rules) | H7: 0 | I7: 1274 | J7: No; Yes | K7: ordered
A8: C7 | B8: Does your child look at a person when that person starts talking or making noise? | C8: GSED SF | D8: 0 months | E8: 42 months | F8: Yes; No; Don't Know | G8: All (Age Band Rules) | H8: 0 | I8: 1274 | J8: No; Yes | K8: ordered
A9: C8 | B9: Does your child hold his/her hands in fists all the time? | C9: GSED SF | D9: 0 months | E9: 42 months | F9: Yes; No; Don't Know | G9: All (Age Band Rules) | H9: 0 | I9: 1274 | J9: No; Yes | K9: ordered
A10: C9 | B10: Does your child make sounds other than crying? | C10: GSED SF | D10: 0 months | E10: 42 months | F10: Yes; No; Don't Know | G10: All (Age Band Rules) | H10: 0 | I10: 1274 | J10: No; Yes | K10: ordered
A11: C10 | B11: Does your child smile when you smile or talk with him/her? | C11: GSED SF | D11: 0 months | E11: 42 months | F11: Yes; No; Don't Know | G11: All (Age Band Rules) | H11: 0 | I11: 1274 | J11: No; Yes | K11: ordered
A12: C11 | B12: Does your child bring his/her hand to his/her mouth? | C12: GSED SF | D12: 0 months | E12: 42 months | F12: Yes; No; Don't Know | G12: All (Age Band Rules) | H12: 0 | I12: 1274 | J12: No; Yes | K12: ordered
A13: C12 | B13: When you talk to your child, does he/she smile, make noises, or move arms, legs or trunk in response? | C13: GSED SF | D13: 0 months | E13: 42 months | F13: Yes; No; Don't Know | G13: All (Age Band Rules) | H13: 0 | I13: 1274 | J13: No; Yes | K13: ordered
... A212: NOM62 | B212: How often does this child have difficulty when moving between one activity and a new one? | C212: Emotional regulation | D212: 30 months | E212: 60 months | F212: None of the time, some of the time, half of the time, most of the time, all of the time | G212: All (Age Band Rules) | H212: 910 | I212: 1826 | J212: None of the time; Some of the time; Half of the time; Most of the time; All of the time | K212: ordered
